Workbook
Name flight_time: Model!$H$1:$H$1093
Name mean11am: IO!$H$4
Name mean3pm: IO!$H$5
Name mean7pm: IO!$H$6
Name std_dev11am: IO!$I$4
Name std_dev3pm: IO!$I$5

Sheet Assignment Details

Sheet Data Sheet
A1: Flight | B1: Day | C1: Date | D1: Time | E1: No Shows | F1: Demand
A2: 1 | B2: Fri | C2: 44197 | D2: 11am | E2: 5 | F2: 95
A3: 2 | B3: Fri | C3: 44197 | D3: 3pm | E3: 4 | F3: 97
A4: 3 | B4: Fri | C4: 44197 | D4: 7pm | E4: 0 | F4: 112
A5: 4 | B5: Sat | C5: 44198 | D5: 11am | E5: 3 | F5: 103
A6: 5 | B6: Sat | C6: 44198 | D6: 3pm | E6: 2 | F6: 108
A7: 6 | B7: Sat | C7: 44198 | D7: 7pm | E7: 2 | F7: 107
A8: 7 | B8: Sun | C8: 44199 | D8: 11am | E8: 7 | F8: 105
A9: 8 | B9: Sun | C9: 44199 | D9: 3pm | E9: 3 | F9: 108
A10: 9 | B10: Sun | C10: 44199 | D10: 7pm | E10: 1 | F10: 109
A11: 10 | B11: Mon | C11: 44200 | D11: 11am | E11: 2 | F11: 104
A12: 11 | B12: Mon | C12: 44200 | D12: 3pm | E12: 4 | F12: 104
A13: 12 | B13: Mon | C13: 44200 | D13: 7pm | E13: 0 | F13: 103
... A1093: 1092 | B1093: Fri | C1093: 44561 | D1093: 7pm | E1093: 2 | F1093: 110

Sheet FData
A1: Flight Number | B1: Number of No Shows | E1: Probability Distribution for Number of No Shows
A2: 1 | B2: 5 | E2: No Shows | F2: Count | G2: Probability
A3: 2 | B3: 4 | E3: 0 | F3: =COUNTIF(B2:B318,0) -> 36 | G3: =F3/F12 -> 0.11428571
A4: 17 | B4: 2 | E4: 1 | F4: =COUNTIF(B2:B318,1) -> 72 | G4: =F4/F12 -> 0.22857143
A5: 18 | B5: 2 | E5: 2 | F5: =COUNTIF(B2:B318,2) -> 60 | G5: =F5/F12 -> 0.19047619
A6: 19 | B6: 4 | E6: 3 | F6: =COUNTIF(B3:B319,3) -> 58 | G6: =F6/F12 -> 0.18412698
A7: 22 | B7: 4 | E7: 4 | F7: =COUNTIF(B4:B320,4) -> 45 | G7: =F7/F12 -> 0.14285714
A8: 25 | B8: 3 | E8: 5 | F8: =COUNTIF(B5:B321,5) -> 23 | G8: =F8/F12 -> 0.073015873
A9: 31 | B9: 4 | E9: 6 | F9: =COUNTIF(B6:B322,6) -> 12 | G9: =F9/F12 -> 0.038095238
A10: 32 | B10: 2 | E10: 7 | F10: =COUNTIF(B7:B323,7) -> 5 | G10: =F10/F12 -> 0.015873016
A11: 33 | B11: 0 | E11: 8 | F11: =COUNTIF(B8:B324,8) -> 4 | G11: =F11/F12 -> 0.012698413
A12: 34 | B12: 1 | E12: TOTAL | F12: =SUM(F3:F11) -> 315 | G12: =SUM(G3:G11) -> 1
A13: 35 | B13: 2
A14: 36 | B14: 0
A15: 38 | B15: 2 | E15: Cum. Probability Distribution
A16: 49 | B16: 2 | E16: No Shows | F16: Probability
A17: 52 | B17: 5 | E17: <0 | F17: 0
A18: 54 | B18: 2 | E18: <1 | F18: =G3 -> 0.11428571
A19: 55 | B19: 2 | E19: <2 | F19: =F18+G4 -> 0.34285714
A20: 56 | B20: 3 | E20: <3 | F20: =F19+G5 -> 0.53333333
A21: 58 | B21: 4 | E21: <4 | F21: =F20+G6 -> 0.71746032
A22: 64 | B22: 3 | E22: <5 | F22: =F21+G7 -> 0.86031746
A23: 69 | B23: 3 | E23: <6 | F23: =F22+G8 -> 0.93333333
A24: 70 | B24: 3 | E24: <7 | F24: =F23+G9 -> 0.97142857
A25: 71 | B25: 3 | E25: <8 | F25: =F24+G10 -> 0.98730159
A26: 73 | B26: 5
A27: 79 | B27: 5
A28: 80 | B28: 3 | E28: Vlookup Table
A29: 97 | B29: 1 | E29: No Shows | F29: Probability
A30: 100 | B30: 3 | E30: =F17 -> 0 | F30: 0
A31: 106 | B31: 3 | E31: =F18 -> 0.11428571 | F31: 1
A32: 107 | B32: 2 | E32: =F19 -> 0.34285714 | F32: 2
A33: 112 | B33: 4 | E33: =F20 -> 0.53333333 | F33: 3
A34: 113 | B34: 3 | E34: =F21 -> 0.71746032 | F34: 4
A35: 115 | B35: 3 | E35: =F22 -> 0.86031746 | F35: 5
A36: 118 | B36: 1 | E36: =F23 -> 0.93333333 | F36: 6
A37: 119 | B37: 0 | E37: =F24 -> 0.97142857 | F37: 7
A38: 121 | B38: 5 | E38: =F25 -> 0.98730159 | F38: 8
A39: 122 | B39: 3
A40: 123 | B40: 0
...

Sheet Model
A1: Flight Number | B1: No. of no shows | C1: No. of bookings | D1: Bumped | E1: Profit | G1: Flight number | H1: flight time | I1: No. of no shows | J1: Random number | K1: demand | L1: no. of bookings | M1: bumped | N1: profit
A2: 1 | B2: 5 | C2: =(IO!$B$4+IO!$B$8) -> 102 | D2: =IF(B2>IO!$B$8,0,IO!$B$8-Model!B2) -> 0 | E2: =IO!$B$5*C2-IO!$B$6*D2 -> 4080 | G2: 1 | H2: 11am | I2: 5 | J2: 0.59763419 | K2: =ROUND(NORMINV(J2,IO!$B$10,IO!$B$11),0) -> 104 | L2: =MIN(K2,IO!$B$4+IO!$B$8) -> 102 | M2: =IF(L2-I2>IO!$B$4,Model!L2-Model!I2-IO!$B$4,0) -> 0 | N2: =IO!$B$5*Model!L2-IO!$B$6*Model!M2 -> 4080
A3: 2 | B3: 4 | C3: =(IO!$B$4+IO!$B$8) -> 102 | D3: =IF(B3>IO!$B$8,0,IO!$B$8-Model!B3) -> 0 | E3: =IO!$B$5*C3-IO!$B$6*D3 -> 4080 | G3: 2 | H3: 3pm | I3: 4 | J3: 0.35297749 | K3: =ROUND(NORMINV(J3,IO!$B$10,IO!$B$11),0) -> 101 | L3: =MIN(K3,IO!$B$4+IO!$B$8) -> 101 | M3: =IF(L3-I3>IO!$B$4,Model!L3-Model!I3-IO!$B$4,0) -> 0 | N3: =IO!$B$5*Model!L3-IO!$B$6*Model!M3 -> 4040
A4: 3 | B4: 0 | C4: =(IO!$B$4+IO!$B$8) -> 102 | D4: =IF(B4>IO!$B$8,0,IO!$B$8-Model!B4) -> 2 | E4: =IO!$B$5*C4-IO!$B$6*D4 -> 3880 | G4: 3 | H4: 7pm | I4: 0 | J4: 0.758986 | K4: =ROUND(NORMINV(J4,IO!$B$10,IO!$B$11),0) -> 107 | L4: =MIN(K4,IO!$B$4+IO!$B$8) -> 102 | M4: =IF(L4-I4>IO!$B$4,Model!L4-Model!I4-IO!$B$4,0) -> 2 | N4: =IO!$B$5*Model!L4-IO!$B$6*Model!M4 -> 3880
A5: 4 | B5: 3 | C5: =(IO!$B$4+IO!$B$8) -> 102 | D5: =IF(B5>IO!$B$8,0,IO!$B$8-Model!B5) -> 0 | E5: =IO!$B$5*C5-IO!$B$6*D5 -> 4080 | G5: 4 | H5: 11am | I5: 3 | J5: 0.57294663 | K5: =ROUND(NORMINV(J5,IO!$B$10,IO!$B$11),0) -> 104 | L5: =MIN(K5,IO!$B$4+IO!$B$8) -> 102 | M5: =IF(L5-I5>IO!$B$4,Model!L5-Model!I5-IO!$B$4,0) -> 0 | N5: =IO!$B$5*Model!L5-IO!$B$6*Model!M5 -> 4080
A6: 5 | B6: 2 | C6: =(IO!$B$4+IO!$B$8) -> 102 | D6: =IF(B6>IO!$B$8,0,IO!$B$8-Model!B6) -> 0 | E6: =IO!$B$5*C6-IO!$B$6*D6 -> 4080 | G6: 5 | H6: 3pm | I6: 2 | J6: 0.74099491 | K6: =ROUND(NORMINV(J6,IO!$B$10,IO!$B$11),0) -> 106 | L6: =MIN(K6,IO!$B$4+IO!$B$8) -> 102 | M6: =IF(L6-I6>IO!$B$4,Model!L6-Model!I6-IO!$B$4,0) -> 0 | N6: =IO!$B$5*Model!L6-IO!$B$6*Model!M6 -> 4080
A7: 6 | B7: 2 | C7: =(IO!$B$4+IO!$B$8) -> 102 | D7: =IF(B7>IO!$B$8,0,IO!$B$8-Model!B7) -> 0 | E7: =IO!$B$5*C7-IO!$B$6*D7 -> 4080 | G7: 6 | H7: 7pm | I7: 2 | J7: 0.33283066 | K7: =ROUND(NORMINV(J7,IO!$B$10,IO!$B$11),0) -> 101 | L7: =MIN(K7,IO!$B$4+IO!$B$8) -> 101 | M7: =IF(L7-I7>IO!$B$4,Model!L7-Model!I7-IO!$B$4,0) -> 0 | N7: =IO!$B$5*Model!L7-IO!$B$6*Model!M7 -> 4040
A8: 7 | B8: 7 | C8: =(IO!$B$4+IO!$B$8) -> 102 | D8: =IF(B8>IO!$B$8,0,IO!$B$8-Model!B8) -> 0 | E8: =IO!$B$5*C8-IO!$B$6*D8 -> 4080 | G8: 7 | H8: 11am | I8: 7 | J8: 0.72787883 | K8: =ROUND(NORMINV(J8,IO!$B$10,IO!$B$11),0) -> 106 | L8: =MIN(K8,IO!$B$4+IO!$B$8) -> 102 | M8: =IF(L8-I8>IO!$B$4,Model!L8-Model!I8-IO!$B$4,0) -> 0 | N8: =IO!$B$5*Model!L8-IO!$B$6*Model!M8 -> 4080
A9: 8 | B9: 3 | C9: =(IO!$B$4+IO!$B$8) -> 102 | D9: =IF(B9>IO!$B$8,0,IO!$B$8-Model!B9) -> 0 | E9: =IO!$B$5*C9-IO!$B$6*D9 -> 4080 | G9: 8 | H9: 3pm | I9: 3 | J9: 0.7152127 | K9: =ROUND(NORMINV(J9,IO!$B$10,IO!$B$11),0) -> 106 | L9: =MIN(K9,IO!$B$4+IO!$B$8) -> 102 | M9: =IF(L9-I9>IO!$B$4,Model!L9-Model!I9-IO!$B$4,0) -> 0 | N9: =IO!$B$5*Model!L9-IO!$B$6*Model!M9 -> 4080
A10: 9 | B10: 1 | C10: =(IO!$B$4+IO!$B$8) -> 102 | D10: =IF(B10>IO!$B$8,0,IO!$B$8-Model!B10) -> 1 | E10: =IO!$B$5*C10-IO!$B$6*D10 -> 3980 | G10: 9 | H10: 7pm | I10: 1 | J10: 0.38334238 | K10: =ROUND(NORMINV(J10,IO!$B$10,IO!$B$11),0) -> 102 | L10: =MIN(K10,IO!$B$4+IO!$B$8) -> 102 | M10: =IF(L10-I10>IO!$B$4,Model!L10-Model!I10-IO!$B$4,0) -> 1 | N10: =IO!$B$5*Model!L10-IO!$B$6*Model!M10 -> 3980
A11: 10 | B11: 2 | C11: =(IO!$B$4+IO!$B$8) -> 102 | D11: =IF(B11>IO!$B$8,0,IO!$B$8-Model!B11) -> 0 | E11: =IO!$B$5*C11-IO!$B$6*D11 -> 4080 | G11: 10 | H11: 11am | I11: 2 | J11: 0.0010316865 | K11: =ROUND(NORMINV(J11,IO!$B$10,IO!$B$11),0) -> 88 | L11: =MIN(K11,IO!$B$4+IO!$B$8) -> 88 | M11: =IF(L11-I11>IO!$B$4,Model!L11-Model!I11-IO!$B$4,0) -> 0 | N11: =IO!$B$5*Model!L11-IO!$B$6*Model!M11 -> 3520
A12: 11 | B12: 4 | C12: =(IO!$B$4+IO!$B$8) -> 102 | D12: =IF(B12>IO!$B$8,0,IO!$B$8-Model!B12) -> 0 | E12: =IO!$B$5*C12-IO!$B$6*D12 -> 4080 | G12: 11 | H12: 3pm | I12: 4 | J12: 0.67450057 | K12: =ROUND(NORMINV(J12,IO!$B$10,IO!$B$11),0) -> 105 | L12: =MIN(K12,IO!$B$4+IO!$B$8) -> 102 | M12: =IF(L12-I12>IO!$B$4,Model!L12-Model!I12-IO!$B$4,0) -> 0 | N12: =IO!$B$5*Model!L12-IO!$B$6*Model!M12 -> 4080
A13: 12 | B13: 0 | C13: =(IO!$B$4+IO!$B$8) -> 102 | D13: =IF(B13>IO!$B$8,0,IO!$B$8-Model!B13) -> 2 | E13: =IO!$B$5*C13-IO!$B$6*D13 -> 3880 | G13: 12 | H13: 7pm | I13: 0 | J13: 0.34528199 | K13: =ROUND(NORMINV(J13,IO!$B$10,IO!$B$11),0) -> 101 | L13: =MIN(K13,IO!$B$4+IO!$B$8) -> 101 | M13: =IF(L13-I13>IO!$B$4,Model!L13-Model!I13-IO!$B$4,0) -> 1 | N13: =IO!$B$5*Model!L13-IO!$B$6*Model!M13 -> 3940
... A1093: 1092 | B1093: 2 | C1093: =(IO!$B$4+IO!$B$8) -> 102 | D1093: =IF(B1093>IO!$B$8,0,IO!$B$8-Model!B1093) -> 0 | E1093: =IO!$B$5*C1093-IO!$B$6*D1093 -> 4080 | G1093: 1092 | H1093: 7pm | I1093: 2 | J1093: 0.10606262 | K1093: =ROUND(NORMINV(J1093,IO!$B$10,IO!$B$11),0) -> 97 | L1093: =MIN(K1093,IO!$B$4+IO!$B$8) -> 97 | M1093: =IF(L1093-I1093>IO!$B$4,Model!L1093-Model!I1093-IO!$B$4,0) -> 0 | N1093: =IO!$B$5*Model!L1093-IO!$B$6*Model!M1093 -> 3880

Sheet IO
A2: Inputs | D2: OUTPUT
A3: Fixed parameters | D3: PROFIT STATISTICS | H3: mean | I3: std dev
A4: Plane capacity | B4: 100 | E4: Profit | G4: 0.45833333 | H4: 101 | I4: 6
A5: profit per booking | B5: 40 | D5: Average | E5: =AVERAGE(Model!E2:E1093) -> 4023.315 | G5: 0.625 | H5: 103 | I5: 5
A6: Average cost of bumped passenger | B6: 100 | D6: Std Dev | E6: =STDEV(Model!E2:E1093) -> 76.717724 | G6: 0.79166667 | H6: 105 | I6: 5
A7: Strategy | D7: Max | E7: =MAX(Model!E2:E1093) -> 4080
A8: No. of overbookings | B8: 2 | D8: Min | E8: =MIN(Model!E2:E1093) -> 3880
A9: Random variables
A10: Mean demand | B10: 103
A11: Std deviation of demand | B11: 5 | D11: Av. Profit | E11: NUMBER OF OVERBOOKINGS
D12: =E5 -> 4023.315 | E12: 0 | F12: 1 | G12: 2 | H12: 3 | I12: 4 | J12: 5
D13: 100 | E13: 4000 | F13: 4022.8755 | G13: 4023.315 | H13: 4002.326 | I13: 3965.3114 | J13: 3917.5824
A14: Vlookup table simulating no shows
A15: Bin | B15: No shows
A16: =FData!F17 -> 0 | B16: 0 | D16: Sensitivity analysis
A17: =FData!E31 -> 0.11428571 | B17: 1 | E17: Avg. Profit | F17: Number of overbookings
A18: =FData!E32 -> 0.34285714 | B18: 2 | D18: Flight Time | E18: =E5 -> 4023.315 | F18: 1 | G18: 2 | H18: 3 | I18: 4 | J18: 5
A19: =FData!E33 -> 0.53333333 | B19: 3 | D19: 11 am and 3pm | E19: 25 | F19: 4035.7189 | G19: 4065.8288 | H19: 4090.5815 | I19: 4111.3278 | J19: 4129.3956
A20: =FData!E34 -> 0.71746032 | B20: 4 | D20: 7 pm | E20: 200 | F20: 4005.7509 | G20: 3966.63 | H20: 3884.652 | I20: 3770.6227 | J20: 3635.1648
A21: =FData!E35 -> 0.86031746 | B21: 5
A22: =FData!E36 -> 0.93333333 | B22: 6
A23: =FData!E37 -> 0.97142857 | B23: 7
A24: =FData!E38 -> 0.98730159 | B24: 8

Sheet Assumptions
A1: Assumptions:
A2: 1.) The maximum capacity of all flights is 100 passengers
A3: 2.) Profit is fixed for all passengers on every flight
A4: 3.) Fixed loss per passenger for overbooking
A6: Evaluation
A7: Based on our sensitivity analysis the 11 am and 3 pm
A8: flights are more profitable for every overbooking made.
A9: In contrast, the 7 pm flight is most profitable with 1 overbooking
A10: and profits continously regress as overbookings increase.
A12: Based on an average cost of €100 for each overbooking we would
A13: recommend an overbooking strategy of 1 or 2.
A14: However based on the different costs of overbooking based on
... A17: to maximise profits.
